2025-01-16 10:39:14,207 INFO    StreamThr :103023 [internal.py:wandb_internal():86] W&B internal server running at pid: 103023, started at: 2025-01-16 10:39:14.206240
2025-01-16 10:39:14,208 DEBUG   HandlerThread:103023 [handler.py:handle_request():146] handle_request: status
2025-01-16 10:39:14,210 INFO    WriterThread:103023 [datastore.py:open_for_write():87] open: /user/ma4177/Exp_neural/wandb/run-20250116_103914-y33d6ve4/run-y33d6ve4.wandb
2025-01-16 10:39:14,214 DEBUG   SenderThread:103023 [sender.py:send():379] send: header
2025-01-16 10:39:14,225 DEBUG   SenderThread:103023 [sender.py:send():379] send: run
2025-01-16 10:39:14,324 ERROR   SenderThread:103023 [internal_api.py:execute():373] 403 response executing GraphQL.
2025-01-16 10:39:14,324 ERROR   SenderThread:103023 [internal_api.py:execute():374] {"errors":[{"message":"permission denied","path":["upsertBucket"],"extensions":{"code":"PERMISSION_ERROR"}}],"data":{"upsertBucket":null}}
2025-01-16 10:39:14,324 ERROR   SenderThread:103023 [sender.py:send_run():971] It appears that you do not have permission to access the requested resource. Please reach out to the project owner to grant you access. If you have the correct permissions, verify that there are no issues with your networking setup.(Error 403: Forbidden)
Traceback (most recent call last):
  File "/user/ma4177/.conda/envs/exp_neural/lib/python3.10/site-packages/wandb/sdk/lib/retry.py", line 131, in __call__
    result = self._call_fn(*args, **kwargs)
  File "/user/ma4177/.conda/envs/exp_neural/lib/python3.10/site-packages/wandb/sdk/internal/internal_api.py", line 369, in execute
    return self.client.execute(*args, **kwargs)  # type: ignore
  File "/user/ma4177/.conda/envs/exp_neural/lib/python3.10/site-packages/wandb/vendor/gql-0.2.0/wandb_gql/client.py", line 52, in execute
    result = self._get_result(document, *args, **kwargs)
  File "/user/ma4177/.conda/envs/exp_neural/lib/python3.10/site-packages/wandb/vendor/gql-0.2.0/wandb_gql/client.py", line 60, in _get_result
    return self.transport.execute(document, *args, **kwargs)
  File "/user/ma4177/.conda/envs/exp_neural/lib/python3.10/site-packages/wandb/sdk/lib/gql_request.py", line 59, in execute
    request.raise_for_status()
  File "/user/ma4177/.conda/envs/exp_neural/lib/python3.10/site-packages/requests/models.py", line 1024, in raise_for_status
    raise HTTPError(http_error_msg, response=self)
requests.exceptions.HTTPError: 403 Client Error: Forbidden for url: https://api.wandb.ai/graphql

During handling of the above exception, another exception occurred:

Traceback (most recent call last):
  File "/user/ma4177/.conda/envs/exp_neural/lib/python3.10/site-packages/wandb/sdk/internal/sender.py", line 969, in send_run
    server_run = self._init_run(run, config_value_dict)
  File "/user/ma4177/.conda/envs/exp_neural/lib/python3.10/site-packages/wandb/sdk/internal/sender.py", line 1014, in _init_run
    server_run, inserted, server_messages = self._api.upsert_run(
  File "/user/ma4177/.conda/envs/exp_neural/lib/python3.10/site-packages/wandb/apis/normalize.py", line 73, in wrapper
    raise err
  File "/user/ma4177/.conda/envs/exp_neural/lib/python3.10/site-packages/wandb/apis/normalize.py", line 41, in wrapper
    return func(*args, **kwargs)
  File "/user/ma4177/.conda/envs/exp_neural/lib/python3.10/site-packages/wandb/sdk/internal/internal_api.py", line 2217, in upsert_run
    response = self.gql(
  File "/user/ma4177/.conda/envs/exp_neural/lib/python3.10/site-packages/wandb/sdk/internal/internal_api.py", line 341, in gql
    ret = self._retry_gql(
  File "/user/ma4177/.conda/envs/exp_neural/lib/python3.10/site-packages/wandb/sdk/lib/retry.py", line 147, in __call__
    retry_timedelta_triggered = check_retry_fn(e)
  File "/user/ma4177/.conda/envs/exp_neural/lib/python3.10/site-packages/wandb/util.py", line 968, in check_retry_fn
    return fallback_retry_fn(e)
  File "/user/ma4177/.conda/envs/exp_neural/lib/python3.10/site-packages/wandb/util.py", line 910, in no_retry_auth
    raise CommError(
wandb.errors.CommError: It appears that you do not have permission to access the requested resource. Please reach out to the project owner to grant you access. If you have the correct permissions, verify that there are no issues with your networking setup.(Error 403: Forbidden)
2025-01-16 10:39:14,400 DEBUG   HandlerThread:103023 [handler.py:handle_request():146] handle_request: shutdown
2025-01-16 10:39:14,400 INFO    HandlerThread:103023 [handler.py:finish():866] shutting down handler
2025-01-16 10:39:15,225 INFO    WriterThread:103023 [datastore.py:close():296] close: /user/ma4177/Exp_neural/wandb/run-20250116_103914-y33d6ve4/run-y33d6ve4.wandb
2025-01-16 10:39:15,330 INFO    SenderThread:103023 [sender.py:finish():1546] shutting down sender
